Workbook

Sheet Comece aqui
A1: Comece aqui/Start here
A7: Tutoriais, avisos e configurações/Tutorials, warnings and settings
K12: Formas de pagamento | N12: Moeda | Q12: Nomes
B14: AVISOS/WARNINGS | G14: Tema(cor)/Theme (color) | K14: Payment method | N14: Currency | Q14: Names
K15: Débito/debit | L15: Débito | N15: Ao lado, especifique a moeda que deseja usar na sua planilha/Next to it, specify the currency you wish to use in your spreadsheet | O15: R$ | Q15: English | R15: Your language
L16: Pix
G17: Azul/Blue | L17: Boleto | Q17: Inflows | R17: Entradas
L18: Dinheiro | Q18: Investments | R18: Investimentos
B19: • Não é autorizada a revenda e/ou distribuição deste produto./Resale and/or distribution of this product is not authorized. | Q19: Payment Outflows | R19: Saídas por pagamento
Q20: Debit | R20: Débito
G21: Escolha o tema(cor) desejada para a sua planilha. Você pode mudar isto quando quiser/Choose the desired theme (color) for your spreadsheet. You can change this whenever you want. | K21: Crédito/credit | L21: Crédito 1 | Q21: Credit | R21: Crédito
L22: Crédito 2 | Q22: Category | R22: Categoria
B23: • Seguir todas as instruções deste manual e/ou tutoriais anexados para melhor uso/Follow all instructions in this manual and/or attached tutorials for best use. | L23: Crédito 3 | Q23: Outflows | R23: Saídas
L24: Crédito 4 | N24: Dia da semana | Q24: Goals | R24: Metas
L25: Crédito 5 | Q25: Fixed expenses | R25: Gastos fixos
L26: Crédito 6 | N26: Day of the week | Q26: Name | R26: Nome
B27: • Este sistema funciona APENAS no Google planilhas/This system ONLY works in Google Sheets. | N27: Replace the day of the week name with the corresponding name in your language | Q27: Date | R27: Data
G28: Cor do seu gato/Color of your kitty | K28: Mês/month name | Q28: Payment | R28: Pagamento
Q29: Value | R29: Valor
Q30: Limit | R30: Limite
K31: Replace the month name with the corresponding name in your language | Q31: Parcel | R31: Parcela
B32: TUTORIAIS | G32: Frajola/Tuxedo | N32: English | O32: Your language /tu idioma | Q32: =R22 -> Categoria
K33: English | L33: Your language /tu idioma
N34: Sun | O34: Dom | Q34: Coloque aqui o nome das suas categorias de gastos/Enter the names of your spending categories here
K35: January | L35: Janeiro | N35: Mon | O35: Seg
K36: February | L36: Fevereiro | N36: Tue | O36: Ter
B37: COMO CONFIGURAR/HOW TO CONFIGURE | K37: March | L37: Março | N37: Wed | O37: Qua | Q37: Contas
G38: Você deseja que seja descontado no saldo compras no crédito e investimentos? | K38: April | L38: Abril | N38: Thu | O38: Qui | Q38: Saúde
K39: May | L39: Maio | N39: Fri | O39: Sex | Q39: Lazer
K40: June | L40: Junho | N40: Sat | O40: Sab | Q40: Transporte
B41: COMO USAR/ HOW TO USE | K41: July | L41: Julho | Q41: Vestuário
K42: Agust | L42: Agosto | N42: =R24 -> Metas | Q42: Despesas eventuais
K43: September | L43: Setembro | Q43: Ifood
G44: Se sim, clique ao lado | I44: TRUE | K44: October | L44: Outubro | N44: Objetivo dos seus investimentos/Objective of your investments | Q44: Mercado
K45: November | L45: Novembro | Q45: Assinaturas
K46: December | L46: Dezembro | N46: Meta/Goal 1 | Q46: Academia
N47: Meta/Goal 2 | Q47: Presentes
N48: Meta/Goal 3 | Q48: Desenvolvimento
K49: =R26&" "&2 -> Nome 2 | N49: Meta/Goal 4
N50: Meta/Goal 5
...

Sheet Comparativo anual
A1: ='Comece aqui'!L92 -> Comparativo anual
A5: ='Comece aqui'!G17 -> Azul/Blue
B6: Gastos ao longo do ano
C7: ='Comece aqui'!$L35 -> Janeiro | D7: ='Comece aqui'!$L36 -> Fevereiro | E7: ='Comece aqui'!$L37 -> Março | F7: ='Comece aqui'!$L38 -> Abril | G7: ='Comece aqui'!$L39 -> Maio | H7: ='Comece aqui'!$L40 -> Junho | I7: ='Comece aqui'!$L41 -> Julho | J7: ='Comece aqui'!$L42 -> Agosto | K7: ='Comece aqui'!$L43 -> Setembro | L7: ='Comece aqui'!$L44 -> Outubro | M7: ='Comece aqui'!$L45 -> Novembro | N7: ='Comece aqui'!$L46 -> Dezembro
B8: ='Comece aqui'!R17 -> Entradas | C8: =JanuaryJaneiro!Q2 -> 0 | D8: =FebruaryFevereiro!Q2 -> 0 | E8: ='MarchMarço'!Q2 -> 0 | F8: =AprilAbril!Q2 -> 0 | G8: =MayMaio!Q2 -> 0 | H8: =JuneJunho!Q2 -> 0 | I8: =JulyJulho!Q2 -> 0 | J8: =AugustAgosto!Q2 -> 0 | K8: =SeptemberSetembro!Q2 -> 0 | L8: =OctoberOutubro!Q2 -> 0 | M8: =NovemberNovembro!Q2 -> 0 | N8: =DecemberDezembro!Q2 -> 0
B9: ='Comece aqui'!R23 -> Saídas | C9: =JanuaryJaneiro!V2 -> 0 | D9: =FebruaryFevereiro!V2 -> 0 | E9: ='MarchMarço'!V2 -> 0 | F9: =AprilAbril!V2 -> 0 | G9: =MayMaio!V2 -> 0 | H9: =JuneJunho!V2 -> 0 | I9: =JulyJulho!V2 -> 0 | J9: =AugustAgosto!V2 -> 0 | K9: =SeptemberSetembro!V2 -> 0 | L9: =OctoberOutubro!V2 -> 0 | M9: =NovemberNovembro!V2 -> 0 | N9: =DecemberDezembro!V2 -> 0
B10: ='Comece aqui'!L83 -> Diferença | C10: =C8-C9 -> 0 | D10: =D8-D9 -> 0 | E10: =E8-E9 -> 0 | F10: =F8-F9 -> 0 | G10: =G8-G9 -> 0 | H10: =H8-H9 -> 0 | I10: =I8-I9 -> 0 | J10: =J8-J9 -> 0 | ... N10: =N8-N9 -> 0
B12: ='Comece aqui'!L86 -> Quanto entrou no ano | F12: ='Comece aqui'!L89 -> Quando saiu no ano
B14: =B26 -> R$ | C14: =SUM(C8:N8) -> 0 | F14: =F26 -> R$ | G14: =SUM(C9:N9) -> 0
B22: ='Comece aqui'!L77 -> Mês que gastou mais | F22: ='Comece aqui'!L80 -> Mês que gastou menos
B24: =IFS(C26=C9,C7,C26=D9,D7,C26=E9,E7,C26=F9,F7,C26=G9,G7,C26=H9,H7,C26=I9,I7,C26=J9,J7,C26=K9,K7,C26=L9,L7,C26=M9,M7,C26=N9,N7) -> Janeiro | F24: =IFERROR(IFS(G26=C9,C7,G26=D9,D7,G26=E9,E7,G26=F9,F7,G26=G9,G7,G26=H9,H7,G26=I9,I7,G26=J9,J7,G26=K9,K7,G26=L9,L7,G26=M9,M7,G26=N9,N7),"") -> Janeiro | J24: ='Comece aqui'!R22 -> Categoria
B26: ='Comece aqui'!O15 -> R$ | C26: =MAX(C9:N9) -> 0 | F26: ='Comece aqui'!O15 -> R$ | G26: =IFERROR(__xludf.DUMMYFUNCTION("IFERROR(MIN(FILTER(C9:N9, C9:N9<>0)))"),"") | J26: ='Comece aqui'!Q37 -> Contas | L26: ='Comece aqui'!$O$15 -> R$ | M26: =SUM(JanuaryJaneiro!$R46,FebruaryFevereiro!$R46,'MarchMarço'!$R46,AprilAbril!$R46,MayMaio!$R46,JuneJunho!$R46,JulyJulho!$R46,AugustAgosto!$R46,SeptemberSetembro!$R46,OctoberOutubro!$R46,NovemberNovembro!$R46,DecemberDezembro!$R46) -> 0
J27: ='Comece aqui'!Q38 -> Saúde | L27: ='Comece aqui'!$O$15 -> R$ | M27: =SUM(JanuaryJaneiro!$R47,FebruaryFevereiro!$R47,'MarchMarço'!$R47,AprilAbril!$R47,MayMaio!$R47,JuneJunho!$R47,JulyJulho!$R47,AugustAgosto!$R47,SeptemberSetembro!$R47,OctoberOutubro!$R47,NovemberNovembro!$R47,DecemberDezembro!$R47) -> 0
J28: ='Comece aqui'!Q39 -> Lazer | L28: ='Comece aqui'!$O$15 -> R$ | M28: =SUM(JanuaryJaneiro!$R48,FebruaryFevereiro!$R48,'MarchMarço'!$R48,AprilAbril!$R48,MayMaio!$R48,JuneJunho!$R48,JulyJulho!$R48,AugustAgosto!$R48,SeptemberSetembro!$R48,OctoberOutubro!$R48,NovemberNovembro!$R48,DecemberDezembro!$R48) -> 0
J29: ='Comece aqui'!$Q40 -> Transporte | L29: ='Comece aqui'!$O$15 -> R$ | M29: =SUM(JanuaryJaneiro!$R49,FebruaryFevereiro!$R49,'MarchMarço'!$R49,AprilAbril!$R49,MayMaio!$R49,JuneJunho!$R49,JulyJulho!$R49,AugustAgosto!$R49,SeptemberSetembro!$R49,OctoberOutubro!$R49,NovemberNovembro!$R49,DecemberDezembro!$R49) -> 0
J30: ='Comece aqui'!$Q41 -> Vestuário | L30: ='Comece aqui'!$O$15 -> R$ | M30: =SUM(JanuaryJaneiro!$R50,FebruaryFevereiro!$R50,'MarchMarço'!$R50,AprilAbril!$R50,MayMaio!$R50,JuneJunho!$R50,JulyJulho!$R50,AugustAgosto!$R50,SeptemberSetembro!$R50,OctoberOutubro!$R50,NovemberNovembro!$R50,DecemberDezembro!$R50) -> 0
J31: ='Comece aqui'!$Q42 -> Despesas eventuais | L31: ='Comece aqui'!$O$15 -> R$ | M31: =SUM(JanuaryJaneiro!$R51,FebruaryFevereiro!$R51,'MarchMarço'!$R51,AprilAbril!$R51,MayMaio!$R51,JuneJunho!$R51,JulyJulho!$R51,AugustAgosto!$R51,SeptemberSetembro!$R51,OctoberOutubro!$R51,NovemberNovembro!$R51,DecemberDezembro!$R51) -> 0
B32: ='Comece aqui'!L95 -> Categoria com maior gasto | J32: ='Comece aqui'!$Q43 -> Ifood | L32: ='Comece aqui'!$O$15 -> R$ | M32: =SUM(JanuaryJaneiro!$R52,FebruaryFevereiro!$R52,'MarchMarço'!$R52,AprilAbril!$R52,MayMaio!$R52,JuneJunho!$R52,JulyJulho!$R52,AugustAgosto!$R52,SeptemberSetembro!$R52,OctoberOutubro!$R52,NovemberNovembro!$R52,DecemberDezembro!$R52) -> 0
J33: ='Comece aqui'!$Q44 -> Mercado | L33: ='Comece aqui'!$O$15 -> R$ | M33: =SUM(JanuaryJaneiro!$R53,FebruaryFevereiro!$R53,'MarchMarço'!$R53,AprilAbril!$R53,MayMaio!$R53,JuneJunho!$R53,JulyJulho!$R53,AugustAgosto!$R53,SeptemberSetembro!$R53,OctoberOutubro!$R53,NovemberNovembro!$R53,DecemberDezembro!$R53) -> 0
B34: =IFS(C36=M26,J26,C36=M27,J27,C36=M28,J28,C36=M29,J29,C36=M30,J30,C36=M31,J31,C36=M32,J32,C36=M33,J33,C36=M34,J34,C36=M35,J35,C36=M36,J36,C36=M37,J37,C36=M38,J38,C36=M39,J39,C36=M40,J40,C36=M41,J41,C36=M42,J42,C36=M43,J43,C36=M44,J44,C36=M45,J45) -> Contas | J34: ='Comece aqui'!$Q45 -> Assinaturas | L34: ='Comece aqui'!$O$15 -> R$ | M34: =SUM(JanuaryJaneiro!$R54,FebruaryFevereiro!$R54,'MarchMarço'!$R54,AprilAbril!$R54,MayMaio!$R54,JuneJunho!$R54,JulyJulho!$R54,AugustAgosto!$R54,SeptemberSetembro!$R54,OctoberOutubro!$R54,NovemberNovembro!$R54,DecemberDezembro!$R54) -> 0
J35: ='Comece aqui'!$Q46 -> Academia | L35: ='Comece aqui'!$O$15 -> R$ | M35: =SUM(JanuaryJaneiro!$R55,FebruaryFevereiro!$R55,'MarchMarço'!$R55,AprilAbril!$R55,MayMaio!$R55,JuneJunho!$R55,JulyJulho!$R55,AugustAgosto!$R55,SeptemberSetembro!$R55,OctoberOutubro!$R55,NovemberNovembro!$R55,DecemberDezembro!$R55) -> 0
B36: ='Comece aqui'!O15 -> R$ | C36: =MAX(M26:N45) -> 0 | J36: ='Comece aqui'!$Q47 -> Presentes | L36: ='Comece aqui'!$O$15 -> R$ | M36: =SUM(JanuaryJaneiro!$R56,FebruaryFevereiro!$R56,'MarchMarço'!$R56,AprilAbril!$R56,MayMaio!$R56,JuneJunho!$R56,JulyJulho!$R56,AugustAgosto!$R56,SeptemberSetembro!$R56,OctoberOutubro!$R56,NovemberNovembro!$R56,DecemberDezembro!$R56) -> 0
J37: ='Comece aqui'!$Q48 -> Desenvolvimento | L37: ='Comece aqui'!$O$15 -> R$ | M37: =SUM(JanuaryJaneiro!$R57,FebruaryFevereiro!$R57,'MarchMarço'!$R57,AprilAbril!$R57,MayMaio!$R57,JuneJunho!$R57,JulyJulho!$R57,AugustAgosto!$R57,SeptemberSetembro!$R57,OctoberOutubro!$R57,NovemberNovembro!$R57,DecemberDezembro!$R57) -> 0
J38: ='Comece aqui'!$Q49 | L38: ='Comece aqui'!$O$15 -> R$ | M38: =SUM(JanuaryJaneiro!$R58,FebruaryFevereiro!$R58,'MarchMarço'!$R58,AprilAbril!$R58,MayMaio!$R58,JuneJunho!$R58,JulyJulho!$R58,AugustAgosto!$R58,SeptemberSetembro!$R58,OctoberOutubro!$R58,NovemberNovembro!$R58,DecemberDezembro!$R58) -> 0
J39: ='Comece aqui'!$Q50 | L39: ='Comece aqui'!$O$15 -> R$ | M39: =SUM(JanuaryJaneiro!$R59,FebruaryFevereiro!$R59,'MarchMarço'!$R59,AprilAbril!$R59,MayMaio!$R59,JuneJunho!$R59,JulyJulho!$R59,AugustAgosto!$R59,SeptemberSetembro!$R59,OctoberOutubro!$R59,NovemberNovembro!$R59,DecemberDezembro!$R59) -> 0
J40: ='Comece aqui'!$Q51 | L40: ='Comece aqui'!$O$15 -> R$ | M40: =SUM(JanuaryJaneiro!$R60,FebruaryFevereiro!$R60,'MarchMarço'!$R60,AprilAbril!$R60,MayMaio!$R60,JuneJunho!$R60,JulyJulho!$R60,AugustAgosto!$R60,SeptemberSetembro!$R60,OctoberOutubro!$R60,NovemberNovembro!$R60,DecemberDezembro!$R60) -> 0
J41: ='Comece aqui'!$Q52 | L41: ='Comece aqui'!$O$15 -> R$ | M41: =SUM(JanuaryJaneiro!$R61,FebruaryFevereiro!$R61,'MarchMarço'!$R61,AprilAbril!$R61,MayMaio!$R61,JuneJunho!$R61,JulyJulho!$R61,AugustAgosto!$R61,SeptemberSetembro!$R61,OctoberOutubro!$R61,NovemberNovembro!$R61,DecemberDezembro!$R61) -> 0
J42: ='Comece aqui'!$Q53 | L42: ='Comece aqui'!$O$15 -> R$ | M42: =SUM(JanuaryJaneiro!$R62,FebruaryFevereiro!$R62,'MarchMarço'!$R62,AprilAbril!$R62,MayMaio!$R62,JuneJunho!$R62,JulyJulho!$R62,AugustAgosto!$R62,SeptemberSetembro!$R62,OctoberOutubro!$R62,NovemberNovembro!$R62,DecemberDezembro!$R62) -> 0
J43: ='Comece aqui'!$Q54 | L43: ='Comece aqui'!$O$15 -> R$ | M43: =SUM(JanuaryJaneiro!$R63,FebruaryFevereiro!$R63,'MarchMarço'!$R63,AprilAbril!$R63,MayMaio!$R63,JuneJunho!$R63,JulyJulho!$R63,AugustAgosto!$R63,SeptemberSetembro!$R63,OctoberOutubro!$R63,NovemberNovembro!$R63,DecemberDezembro!$R63) -> 0
J44: ='Comece aqui'!$Q55 | L44: ='Comece aqui'!$O$15 -> R$ | M44: =SUM(JanuaryJaneiro!$R64,FebruaryFevereiro!$R64,'MarchMarço'!$R64,AprilAbril!$R64,MayMaio!$R64,JuneJunho!$R64,JulyJulho!$R64,AugustAgosto!$R64,SeptemberSetembro!$R64,OctoberOutubro!$R64,NovemberNovembro!$R64,DecemberDezembro!$R64) -> 0
J45: ='Comece aqui'!$Q56 | L45: ='Comece aqui'!$O$15 -> R$ | M45: =SUM(JanuaryJaneiro!$R65,FebruaryFevereiro!$R65,'MarchMarço'!$R65,AprilAbril!$R65,MayMaio!$R65,JuneJunho!$R65,JulyJulho!$R65,AugustAgosto!$R65,SeptemberSetembro!$R65,OctoberOutubro!$R65,NovemberNovembro!$R65,DecemberDezembro!$R65) -> 0
B47: ='Comece aqui'!R18 -> Investimentos
B49: ='Comece aqui'!$L35 -> Janeiro | C49: ='Comece aqui'!$L36 -> Fevereiro | D49: ='Comece aqui'!$L37 -> Março | E49: ='Comece aqui'!$L38 -> Abril | F49: ='Comece aqui'!$L39 -> Maio | G49: ='Comece aqui'!$L40 -> Junho | H49: ='Comece aqui'!$L41 -> Julho | I49: ='Comece aqui'!$L42 -> Agosto | J49: ='Comece aqui'!$L43 -> Setembro | K49: ='Comece aqui'!$L44 -> Outubro | L49: ='Comece aqui'!$L45 -> Novembro | M49: ='Comece aqui'!$L46 -> Dezembro
B50: =JanuaryJaneiro!M46 -> 0 | C50: =FebruaryFevereiro!M46 -> 0 | D50: ='MarchMarço'!M46 -> 0 | E50: =AprilAbril!M46 -> 0 | F50: =MayMaio!M46 -> 0 | G50: =JuneJunho!M46 -> 0 | H50: =JulyJulho!M46 -> 0 | I50: =AugustAgosto!M46 -> 0 | J50: =SeptemberSetembro!M46 -> 0 | K50: =OctoberOutubro!M46 -> 0 | L50: =NovemberNovembro!M46 -> 0 | M50: =DecemberDezembro!M46 -> 0

Sheet Investimentos
B3: ='Comece aqui'!R18 -> Investimentos | G3: ='Comece aqui'!$N46 -> Meta/Goal 1 | I3: FALSE | K3: ='Comece aqui'!$N47 -> Meta/Goal 2 | M3: FALSE | O3: ='Comece aqui'!$N48 -> Meta/Goal 3 | Q3: FALSE | S3: ='Comece aqui'!$N49 -> Meta/Goal 4 | U3: FALSE | W3: ='Comece aqui'!$N50 -> Meta/Goal 5 | Y3: FALSE | AA3: ='Comece aqui'!$N51 -> Meta/Goal 6 | AC3: FALSE | AE3: ='Comece aqui'!$N52 -> Meta/Goal 7 | AG3: FALSE | AI3: ='Comece aqui'!$N53 -> Meta/Goal 8 | AK3: FALSE | AM3: ='Comece aqui'!$N54 -> Meta/Goal 9 | AO3: FALSE | AQ3: ='Comece aqui'!$N55 -> Meta/Goal 10 | AS3: FALSE
A4: ='Comece aqui'!G17 -> Azul/Blue
G5: Insira aqui foto da meta/Put here your goals picture | K5: Insira aqui foto da meta/Put here your goals picture | O5: Insira aqui foto da meta/Put here your goals picture | S5: Insira aqui foto da meta/Put here your goals picture | W5: Insira aqui foto da meta/Put here your goals picture | AA5: Insira aqui foto da meta/Put here your goals picture | AE5: Insira aqui foto da meta/Put here your goals picture | AI5: Insira aqui foto da meta/Put here your goals picture | AM5: Insira aqui foto da meta/Put here your goals picture | AQ5: Insira aqui foto da meta/Put here your goals picture
B8: ='Comece aqui'!L54 -> Total investido no ano | C8: ='Comece aqui'!$O$15 -> R$ | D8: =SUM(I27,M27,Q27,U27,Y27,AC27,AG27,AK27,AO27,AS27) -> 0
B13: ='Comece aqui'!L56 -> Objetivos | G13: =IFERROR(__xludf.DUMMYFUNCTION("IFERROR(SPARKLINE(I13,{""Charttype"",""Bar"";""Max"",1;""color1"",""c9c2b2""}))"),"") | I13: =iferror(I27/I14,"") | K13: =IFERROR(__xludf.DUMMYFUNCTION("IFERROR(SPARKLINE(M$13,{""Charttype"",""Bar"";""Max"",1;""color1"",""c9c2b2""}))"),"") | M13: =iferror(M27/M14,"") | O13: =IFERROR(__xludf.DUMMYFUNCTION("IFERROR(SPARKLINE(Q13,{""Charttype"",""Bar"";""Max"",1;""color1"",""c9c2b2""}))"),"") | Q13: =iferror(Q27/Q14,"") | S13: =IFERROR(__xludf.DUMMYFUNCTION("IFERROR(SPARKLINE(U13,{""Charttype"",""Bar"";""Max"",1;""color1"",""c9c2b2""}))"),"") | U13: =iferror(U27/U14,"") | W13: =IFERROR(__xludf.DUMMYFUNCTION("IFERROR(SPARKLINE(Y13,{""Charttype"",""Bar"";""Max"",1;""color1"",""c9c2b2""}))"),"") | Y13: =iferror(Y27/Y14,"") | AA13: =IFERROR(__xludf.DUMMYFUNCTION("IFERROR(SPARKLINE(AC13,{""Charttype"",""Bar"";""Max"",1;""color1"",""c9c2b2""}))"),"") | AC13: =iferror(AC27/AC14,"") | AE13: =IFERROR(__xludf.DUMMYFUNCTION("IFERROR(SPARKLINE(AG13,{""Charttype"",""Bar"";""Max"",1;""color1"",""c9c2b2""}))"),"") | AG13: =iferror(AG27/AG14,"") | AI13: =IFERROR(__xludf.DUMMYFUNCTION("IFERROR(SPARKLINE(AK13,{""Charttype"",""Bar"";""Max"",1;""color1"",""c9c2b2""}))"),"") | AK13: =iferror(AK27/AK14,"") | AM13: =IFERROR(__xludf.DUMMYFUNCTION("IFERROR(SPARKLINE(AO13,{""Charttype"",""Bar"";""Max"",1;""color1"",""c9c2b2""}))"),"") | AO13: =iferror(AO27/AO14,"") | AQ13: =IFERROR(__xludf.DUMMYFUNCTION("IFERROR(SPARKLINE(AS13,{""Charttype"",""Bar"";""Max"",1;""color1"",""c9c2b2""}))"),"") | AS13: =iferror(AS27/AS14,"")
G14: ='Comece aqui'!$L$65 -> Valor da meta | H14: ='Comece aqui'!$O$15 -> R$ | K14: ='Comece aqui'!$L$65 -> Valor da meta | L14: ='Comece aqui'!$O$15 -> R$ | O14: ='Comece aqui'!$L$65 -> Valor da meta | P14: ='Comece aqui'!$O$15 -> R$ | S14: ='Comece aqui'!$L$65 -> Valor da meta | T14: ='Comece aqui'!$O$15 -> R$ | W14: ='Comece aqui'!$L$65 -> Valor da meta | X14: ='Comece aqui'!$O$15 -> R$ | AA14: ='Comece aqui'!$L$65 -> Valor da meta | AB14: ='Comece aqui'!$O$15 -> R$ | AE14: ='Comece aqui'!$L$65 -> Valor da meta | AF14: ='Comece aqui'!$O$15 -> R$ | AI14: ='Comece aqui'!$L$65 -> Valor da meta | AJ14: ='Comece aqui'!$O$15 -> R$ | AM14: ='Comece aqui'!$L$65 -> Valor da meta | AN14: ='Comece aqui'!$O$15 -> R$ | AQ14: ='Comece aqui'!$L$65 -> Valor da meta | AR14: ='Comece aqui'!$O$15 -> R$
G15: ='Comece aqui'!$L$35 -> Janeiro | H15: ='Comece aqui'!$O$15 -> R$ | I15: =JanuaryJaneiro!$M36 | K15: ='Comece aqui'!$L$35 -> Janeiro | L15: ='Comece aqui'!$O$15 -> R$ | M15: =JanuaryJaneiro!$M37 | O15: ='Comece aqui'!$L$35 -> Janeiro | P15: ='Comece aqui'!$O$15 -> R$ | Q15: =JanuaryJaneiro!$M38 | S15: ='Comece aqui'!$L$35 -> Janeiro | T15: ='Comece aqui'!$O$15 -> R$ | U15: =JanuaryJaneiro!$M39 | W15: ='Comece aqui'!$L$35 -> Janeiro | X15: ='Comece aqui'!$O$15 -> R$ | Y15: =JanuaryJaneiro!$M40 | AA15: ='Comece aqui'!$L$35 -> Janeiro | AB15: ='Comece aqui'!$O$15 -> R$ | AC15: =JanuaryJaneiro!$M41 | AE15: ='Comece aqui'!$L$35 -> Janeiro | AF15: ='Comece aqui'!$O$15 -> R$ | AG15: =JanuaryJaneiro!$M42 | AI15: ='Comece aqui'!$L$35 -> Janeiro | AJ15: ='Comece aqui'!$O$15 -> R$ | AK15: =JanuaryJaneiro!$M43 | AM15: ='Comece aqui'!$L$35 -> Janeiro | AN15: ='Comece aqui'!$O$15 -> R$ | AO15: =JanuaryJaneiro!$M44 | AQ15: ='Comece aqui'!$L$35 -> Janeiro | AR15: ='Comece aqui'!$O$15 -> R$ | AS15: =JanuaryJaneiro!$M45
B16: ='Comece aqui'!L59 -> Alcançados | C16: =COUNTIF(I3:AS4,true) -> 0 | G16: ='Comece aqui'!$L$36 -> Fevereiro | H16: ='Comece aqui'!$O$15 -> R$ | I16: =FebruaryFevereiro!M36 | K16: ='Comece aqui'!$L$36 -> Fevereiro | L16: ='Comece aqui'!$O$15 -> R$ | M16: =FebruaryFevereiro!M37 | O16: ='Comece aqui'!$L$36 -> Fevereiro | P16: ='Comece aqui'!$O$15 -> R$ | Q16: =FebruaryFevereiro!M38 | S16: ='Comece aqui'!$L$36 -> Fevereiro | T16: ='Comece aqui'!$O$15 -> R$ | U16: =FebruaryFevereiro!M39 | W16: ='Comece aqui'!$L$36 -> Fevereiro | X16: ='Comece aqui'!$O$15 -> R$ | Y16: =FebruaryFevereiro!M40 | AA16: ='Comece aqui'!$L$36 -> Fevereiro | AB16: ='Comece aqui'!$O$15 -> R$ | AC16: =FebruaryFevereiro!M41 | AE16: ='Comece aqui'!$L$36 -> Fevereiro | AF16: ='Comece aqui'!$O$15 -> R$ | AG16: =FebruaryFevereiro!M42 | AI16: ='Comece aqui'!$L$36 -> Fevereiro | AJ16: ='Comece aqui'!$O$15 -> R$ | AK16: =FebruaryFevereiro!M43 | AM16: ='Comece aqui'!$L$36 -> Fevereiro | AN16: ='Comece aqui'!$O$15 -> R$ | AO16: =FebruaryFevereiro!M44 | AQ16: ='Comece aqui'!$L$36 -> Fevereiro | AR16: ='Comece aqui'!$O$15 -> R$ | AS16: =FebruaryFevereiro!$M45
G17: ='Comece aqui'!$L$37 -> Março | H17: ='Comece aqui'!$O$15 -> R$ | I17: ='MarchMarço'!$M36 | K17: ='Comece aqui'!$L$37 -> Março | L17: ='Comece aqui'!$O$15 -> R$ | M17: ='MarchMarço'!$M37 | O17: ='Comece aqui'!$L$37 -> Março | P17: ='Comece aqui'!$O$15 -> R$ | Q17: ='MarchMarço'!$M38 | S17: ='Comece aqui'!$L$37 -> Março | T17: ='Comece aqui'!$O$15 -> R$ | U17: ='MarchMarço'!$M39 | W17: ='Comece aqui'!$L$37 -> Março | X17: ='Comece aqui'!$O$15 -> R$ | Y17: ='MarchMarço'!$M40 | AA17: ='Comece aqui'!$L$37 -> Março | AB17: ='Comece aqui'!$O$15 -> R$ | AC17: ='MarchMarço'!$M41 | AE17: ='Comece aqui'!$L$37 -> Março | AF17: ='Comece aqui'!$O$15 -> R$ | AG17: ='MarchMarço'!$M42 | AI17: ='Comece aqui'!$L$37 -> Março | AJ17: ='Comece aqui'!$O$15 -> R$ | AK17: ='MarchMarço'!$M43 | AM17: ='Comece aqui'!$L$37 -> Março | AN17: ='Comece aqui'!$O$15 -> R$ | AO17: ='MarchMarço'!$M44 | AQ17: ='Comece aqui'!$L$37 -> Março | AR17: ='Comece aqui'!$O$15 -> R$ | AS17: ='MarchMarço'!$M45
B18: ='Comece aqui'!L62 -> Pendentes | C18: =COUNTIF(I3:AS4,false) -> 10 | G18: ='Comece aqui'!$L$38 -> Abril | H18: ='Comece aqui'!$O$15 -> R$ | I18: =AprilAbril!M36 | K18: ='Comece aqui'!$L$38 -> Abril | L18: ='Comece aqui'!$O$15 -> R$ | M18: =AprilAbril!M37 | O18: ='Comece aqui'!$L$38 -> Abril | P18: ='Comece aqui'!$O$15 -> R$ | Q18: =AprilAbril!M38 | S18: ='Comece aqui'!$L$38 -> Abril | T18: ='Comece aqui'!$O$15 -> R$ | U18: =AprilAbril!M39 | W18: ='Comece aqui'!$L$38 -> Abril | X18: ='Comece aqui'!$O$15 -> R$ | Y18: =AprilAbril!M40 | AA18: ='Comece aqui'!$L$38 -> Abril | AB18: ='Comece aqui'!$O$15 -> R$ | AC18: =AprilAbril!M41 | AE18: ='Comece aqui'!$L$38 -> Abril | AF18: ='Comece aqui'!$O$15 -> R$ | AG18: =AprilAbril!M42 | AI18: ='Comece aqui'!$L$38 -> Abril | AJ18: ='Comece aqui'!$O$15 -> R$ | AK18: =AprilAbril!M43 | AM18: ='Comece aqui'!$L$38 -> Abril | AN18: ='Comece aqui'!$O$15 -> R$ | AO18: =AprilAbril!M44 | AQ18: ='Comece aqui'!$L$38 -> Abril | AR18: ='Comece aqui'!$O$15 -> R$ | AS18: =AprilAbril!M45
G19: ='Comece aqui'!$L$39 -> Maio | H19: ='Comece aqui'!$O$15 -> R$ | I19: =MayMaio!M36 | K19: ='Comece aqui'!$L$39 -> Maio | L19: ='Comece aqui'!$O$15 -> R$ | M19: =MayMaio!M37 | O19: ='Comece aqui'!$L$39 -> Maio | P19: ='Comece aqui'!$O$15 -> R$ | Q19: =MayMaio!M38 | S19: ='Comece aqui'!$L$39 -> Maio | T19: ='Comece aqui'!$O$15 -> R$ | U19: =MayMaio!M39 | W19: ='Comece aqui'!$L$39 -> Maio | X19: ='Comece aqui'!$O$15 -> R$ | Y19: =MayMaio!M40 | AA19: ='Comece aqui'!$L$39 -> Maio | AB19: ='Comece aqui'!$O$15 -> R$ | AC19: =MayMaio!M41 | AE19: ='Comece aqui'!$L$39 -> Maio | AF19: ='Comece aqui'!$O$15 -> R$ | AG19: =MayMaio!M42 | AI19: ='Comece aqui'!$L$39 -> Maio | AJ19: ='Comece aqui'!$O$15 -> R$ | AK19: =MayMaio!M43 | AM19: ='Comece aqui'!$L$39 -> Maio | AN19: ='Comece aqui'!$O$15 -> R$ | AO19: =MayMaio!M44 | AQ19: ='Comece aqui'!$L$39 -> Maio | AR19: ='Comece aqui'!$O$15 -> R$ | AS19: =MayMaio!M45
G20: ='Comece aqui'!$L$40 -> Junho | H20: ='Comece aqui'!$O$15 -> R$ | I20: =JuneJunho!M36 | K20: ='Comece aqui'!$L$40 -> Junho | L20: ='Comece aqui'!$O$15 -> R$ | M20: =JuneJunho!M37 | O20: ='Comece aqui'!$L$40 -> Junho | P20: ='Comece aqui'!$O$15 -> R$ | Q20: =JuneJunho!M38 | S20: ='Comece aqui'!$L$40 -> Junho | T20: ='Comece aqui'!$O$15 -> R$ | U20: =JuneJunho!M39 | W20: ='Comece aqui'!$L$40 -> Junho | X20: ='Comece aqui'!$O$15 -> R$ | Y20: =JuneJunho!M40 | AA20: ='Comece aqui'!$L$40 -> Junho | AB20: ='Comece aqui'!$O$15 -> R$ | AC20: =JuneJunho!M41 | AE20: ='Comece aqui'!$L$40 -> Junho | AF20: ='Comece aqui'!$O$15 -> R$ | AG20: =JuneJunho!M42 | AI20: ='Comece aqui'!$L$40 -> Junho | AJ20: ='Comece aqui'!$O$15 -> R$ | AK20: =JuneJunho!M43 | AM20: ='Comece aqui'!$L$40 -> Junho | AN20: ='Comece aqui'!$O$15 -> R$ | AO20: =JuneJunho!M44 | AQ20: ='Comece aqui'!$L$40 -> Junho | AR20: ='Comece aqui'!$O$15 -> R$ | AS20: =JuneJunho!M45
B21: ='Comece aqui'!L74 -> Total por mês | G21: ='Comece aqui'!$L$41 -> Julho | H21: ='Comece aqui'!$O$15 -> R$ | I21: =JulyJulho!$M$36 | K21: ='Comece aqui'!$L$41 -> Julho | L21: ='Comece aqui'!$O$15 -> R$ | M21: =JulyJulho!M37 | O21: ='Comece aqui'!$L$41 -> Julho | P21: ='Comece aqui'!$O$15 -> R$ | Q21: =JulyJulho!$M38 | S21: ='Comece aqui'!$L$41 -> Julho | T21: ='Comece aqui'!$O$15 -> R$ | U21: =JulyJulho!M39 | W21: ='Comece aqui'!$L$41 -> Julho | X21: ='Comece aqui'!$O$15 -> R$ | Y21: =JulyJulho!M40 | AA21: ='Comece aqui'!$L$41 -> Julho | AB21: ='Comece aqui'!$O$15 -> R$ | AC21: =JulyJulho!M41 | AE21: ='Comece aqui'!$L$41 -> Julho | AF21: ='Comece aqui'!$O$15 -> R$ | AG21: =JulyJulho!M42 | AI21: ='Comece aqui'!$L$41 -> Julho | AJ21: ='Comece aqui'!$O$15 -> R$ | AK21: =JulyJulho!M43 | AM21: ='Comece aqui'!$L$41 -> Julho | AN21: ='Comece aqui'!$O$15 -> R$ | AO21: =JulyJulho!M44 | AQ21: ='Comece aqui'!$L$41 -> Julho | AR21: ='Comece aqui'!$O$15 -> R$ | AS21: =JulyJulho!M45
G22: ='Comece aqui'!$L$42 -> Agosto | H22: ='Comece aqui'!$O$15 -> R$ | I22: =AugustAgosto!$M36 | K22: ='Comece aqui'!$L$42 -> Agosto | L22: ='Comece aqui'!$O$15 -> R$ | M22: =AugustAgosto!$M37 | O22: ='Comece aqui'!$L$42 -> Agosto | P22: ='Comece aqui'!$O$15 -> R$ | Q22: =AugustAgosto!$M38 | S22: ='Comece aqui'!$L$42 -> Agosto | T22: ='Comece aqui'!$O$15 -> R$ | U22: =AugustAgosto!$M39 | W22: ='Comece aqui'!$L$42 -> Agosto | X22: ='Comece aqui'!$O$15 -> R$ | Y22: =AugustAgosto!$M40 | AA22: ='Comece aqui'!$L$42 -> Agosto | AB22: ='Comece aqui'!$O$15 -> R$ | AC22: =AugustAgosto!$M41 | AE22: ='Comece aqui'!$L$42 -> Agosto | AF22: ='Comece aqui'!$O$15 -> R$ | AG22: =AugustAgosto!$M42 | AI22: ='Comece aqui'!$L$42 -> Agosto | AJ22: ='Comece aqui'!$O$15 -> R$ | AK22: =AugustAgosto!$M43 | AM22: ='Comece aqui'!$L$42 -> Agosto | AN22: ='Comece aqui'!$O$15 -> R$ | AO22: =AugustAgosto!$M44 | AQ22: ='Comece aqui'!$L$42 -> Agosto | AR22: ='Comece aqui'!$O$15 -> R$
B23: ='Comece aqui'!$L$35 -> Janeiro | C23: ='Comece aqui'!$O$15 -> R$ | D23: =Sum(I15,M15,Q15,U15,Y15,AC15,AG15,AK15,AO15,AS15) -> 0 | G23: ='Comece aqui'!$L$43 -> Setembro | H23: ='Comece aqui'!$O$15 -> R$ | I23: =SeptemberSetembro!$M36 | K23: ='Comece aqui'!$L$43 -> Setembro | L23: ='Comece aqui'!$O$15 -> R$ | M23: =SeptemberSetembro!$M37 | O23: ='Comece aqui'!$L$43 -> Setembro | P23: ='Comece aqui'!$O$15 -> R$ | Q23: =SeptemberSetembro!$M38 | S23: ='Comece aqui'!$L$43 -> Setembro | T23: ='Comece aqui'!$O$15 -> R$ | U23: =SeptemberSetembro!$M39 | W23: ='Comece aqui'!$L$43 -> Setembro | X23: ='Comece aqui'!$O$15 -> R$ | Y23: =SeptemberSetembro!$M40 | AA23: ='Comece aqui'!$L$43 -> Setembro | AB23: ='Comece aqui'!$O$15 -> R$ | AC23: =SeptemberSetembro!$M41 | AE23: ='Comece aqui'!$L$43 -> Setembro | AF23: ='Comece aqui'!$O$15 -> R$ | AG23: =SeptemberSetembro!$M42 | AI23: ='Comece aqui'!$L$43 -> Setembro | AJ23: ='Comece aqui'!$O$15 -> R$ | AK23: =SeptemberSetembro!$M43 | AM23: ='Comece aqui'!$L$43 -> Setembro | AN23: ='Comece aqui'!$O$15 -> R$ | AO23: =SeptemberSetembro!$M44 | AQ23: ='Comece aqui'!$L$43 -> Setembro | AR23: ='Comece aqui'!$O$15 -> R$ | AS23: =SeptemberSetembro!$M45
B24: ='Comece aqui'!$L$36 -> Fevereiro | C24: ='Comece aqui'!$O$15 -> R$ | D24: =Sum(I16,M16,Q16,U16,Y16,AC16,AG16,AK16,AO16,AS16) -> 0 | G24: ='Comece aqui'!$L$44 -> Outubro | H24: ='Comece aqui'!$O$15 -> R$ | I24: =OctoberOutubro!$M36 | K24: ='Comece aqui'!$L$44 -> Outubro | L24: ='Comece aqui'!$O$15 -> R$ | M24: =OctoberOutubro!$M37 | O24: ='Comece aqui'!$L$44 -> Outubro | P24: ='Comece aqui'!$O$15 -> R$ | Q24: =OctoberOutubro!$M38 | S24: ='Comece aqui'!$L$44 -> Outubro | T24: ='Comece aqui'!$O$15 -> R$ | U24: =OctoberOutubro!$M39 | W24: ='Comece aqui'!$L$44 -> Outubro | X24: ='Comece aqui'!$O$15 -> R$ | Y24: =OctoberOutubro!$M40 | AA24: ='Comece aqui'!$L$44 -> Outubro | AB24: ='Comece aqui'!$O$15 -> R$ | AC24: =OctoberOutubro!$M41 | AE24: ='Comece aqui'!$L$44 -> Outubro | AF24: ='Comece aqui'!$O$15 -> R$ | AG24: =OctoberOutubro!$M42 | AI24: ='Comece aqui'!$L$44 -> Outubro | AJ24: ='Comece aqui'!$O$15 -> R$ | AK24: =OctoberOutubro!$M43 | AM24: ='Comece aqui'!$L$44 -> Outubro | AN24: ='Comece aqui'!$O$15 -> R$ | AO24: =OctoberOutubro!$M44 | AQ24: ='Comece aqui'!$L$44 -> Outubro | AR24: ='Comece aqui'!$O$15 -> R$ | AS24: =OctoberOutubro!$M45
B25: ='Comece aqui'!$L$37 -> Março | C25: ='Comece aqui'!$O$15 -> R$ | D25: =Sum(I17,M17,Q17,U17,Y17,AC17,AG17,AK17,AO17,AS17) -> 0 | G25: ='Comece aqui'!$L$45 -> Novembro | H25: ='Comece aqui'!$O$15 -> R$ | I25: =NovemberNovembro!M36 | K25: ='Comece aqui'!$L$45 -> Novembro | L25: ='Comece aqui'!$O$15 -> R$ | M25: =NovemberNovembro!M37 | O25: ='Comece aqui'!$L$45 -> Novembro | P25: ='Comece aqui'!$O$15 -> R$ | Q25: =NovemberNovembro!M38 | S25: ='Comece aqui'!$L$45 -> Novembro | T25: ='Comece aqui'!$O$15 -> R$ | U25: =NovemberNovembro!M39 | W25: ='Comece aqui'!$L$45 -> Novembro | X25: ='Comece aqui'!$O$15 -> R$ | Y25: =NovemberNovembro!M40 | AA25: ='Comece aqui'!$L$45 -> Novembro | AB25: ='Comece aqui'!$O$15 -> R$ | AC25: =NovemberNovembro!M41 | AE25: ='Comece aqui'!$L$45 -> Novembro | AF25: ='Comece aqui'!$O$15 -> R$ | AG25: =NovemberNovembro!M42 | AI25: ='Comece aqui'!$L$45 -> Novembro | AJ25: ='Comece aqui'!$O$15 -> R$ | AK25: =NovemberNovembro!M43 | AM25: ='Comece aqui'!$L$45 -> Novembro | AN25: ='Comece aqui'!$O$15 -> R$ | AO25: =NovemberNovembro!M44 | AQ25: ='Comece aqui'!$L$45 -> Novembro | AR25: ='Comece aqui'!$O$15 -> R$ | AS25: =NovemberNovembro!M45
B26: ='Comece aqui'!$L$38 -> Abril | C26: ='Comece aqui'!$O$15 -> R$ | D26: =Sum(I18,M18,Q18,U18,Y18,AC18,AG18,AK18,AO18,AS18) -> 0 | G26: ='Comece aqui'!$L$46 -> Dezembro | H26: ='Comece aqui'!$O$15 -> R$ | I26: =DecemberDezembro!M36 | K26: ='Comece aqui'!$L$46 -> Dezembro | L26: ='Comece aqui'!$O$15 -> R$ | M26: =DecemberDezembro!M37 | O26: ='Comece aqui'!$L$46 -> Dezembro | P26: ='Comece aqui'!$O$15 -> R$ | Q26: =DecemberDezembro!M38 | S26: ='Comece aqui'!$L$46 -> Dezembro | T26: ='Comece aqui'!$O$15 -> R$ | U26: =DecemberDezembro!M39 | W26: ='Comece aqui'!$L$46 -> Dezembro | X26: ='Comece aqui'!$O$15 -> R$ | Y26: =DecemberDezembro!M40 | AA26: ='Comece aqui'!$L$46 -> Dezembro | AB26: ='Comece aqui'!$O$15 -> R$ | AC26: =DecemberDezembro!M41 | AE26: ='Comece aqui'!$L$46 -> Dezembro | AF26: ='Comece aqui'!$O$15 -> R$ | AG26: =DecemberDezembro!M42 | AI26: ='Comece aqui'!$L$46 -> Dezembro | AJ26: ='Comece aqui'!$O$15 -> R$ | AK26: =DecemberDezembro!M43 | AM26: ='Comece aqui'!$L$46 -> Dezembro | AN26: ='Comece aqui'!$O$15 -> R$ | AO26: =DecemberDezembro!M44 | AQ26: ='Comece aqui'!$L$46 -> Dezembro | AR26: ='Comece aqui'!$O$15 -> R$ | AS26: =DecemberDezembro!M45
B27: ='Comece aqui'!$L$39 -> Maio | C27: ='Comece aqui'!$O$15 -> R$ | D27: =Sum(I19,M19,Q19,U19,Y19,AC19,AG19,AK19,AO19,AS19) -> 0 | G27: ='Comece aqui'!$L$68 -> Total da meta | H27: ='Comece aqui'!$O$15 -> R$ | I27: =SUM(I15:I26) -> 0 | K27: ='Comece aqui'!$L$68 -> Total da meta | L27: ='Comece aqui'!$O$15 -> R$ | M27: =SUM(M15:M26) -> 0 | O27: ='Comece aqui'!$L$68 -> Total da meta | P27: ='Comece aqui'!$O$15 -> R$ | Q27: =SUM(Q15:Q26) -> 0 | S27: ='Comece aqui'!$L$68 -> Total da meta | T27: ='Comece aqui'!$O$15 -> R$ | U27: =SUM(U15:U26) -> 0 | W27: ='Comece aqui'!$L$68 -> Total da meta | X27: ='Comece aqui'!$O$15 -> R$ | Y27: =SUM(Y15:Y26) -> 0 | AA27: ='Comece aqui'!$L$68 -> Total da meta | AB27: ='Comece aqui'!$O$15 -> R$ | AC27: =SUM(AC15:AC26) -> 0 | AE27: ='Comece aqui'!$L$68 -> Total da meta | AF27: ='Comece aqui'!$O$15 -> R$ | AG27: =SUM(AG15:AG26) -> 0 | AI27: ='Comece aqui'!$L$68 -> Total da meta | AJ27: ='Comece aqui'!$O$15 -> R$ | AK27: =SUM(AK15:AK26) -> 0 | AM27: ='Comece aqui'!$L$68 -> Total da meta | AN27: ='Comece aqui'!$O$15 -> R$ | AO27: =SUM(AO15:AO26) -> 0 | AQ27: ='Comece aqui'!$L$68 -> Total da meta | AR27: ='Comece aqui'!$O$15 -> R$ | AS27: =SUM(AS15:AS26) -> 0
B28: ='Comece aqui'!$L$40 -> Junho | C28: ='Comece aqui'!$O$15 -> R$ | D28: =Sum(I20,M20,Q20,U20,Y20,AC20,AG20,AK20,AO20,AS20) -> 0 | G28: ='Comece aqui'!$L$71 -> Ainda falta | H28: ='Comece aqui'!$O$15 -> R$ | I28: =iferror(I14-I27,"") -> 0 | K28: ='Comece aqui'!$L$71 -> Ainda falta | L28: ='Comece aqui'!$O$15 -> R$ | M28: =iferror(M14-M27,"") -> 0 | O28: ='Comece aqui'!$L$71 -> Ainda falta | P28: ='Comece aqui'!$O$15 -> R$ | Q28: =iferror(Q14-Q27,"") -> 0 | S28: ='Comece aqui'!$L$71 -> Ainda falta | T28: ='Comece aqui'!$O$15 -> R$ | U28: =iferror(U14-U27,"") -> 0 | W28: ='Comece aqui'!$L$71 -> Ainda falta | X28: ='Comece aqui'!$O$15 -> R$ | Y28: =iferror(Y14-Y27,"") -> 0 | AA28: ='Comece aqui'!$L$71 -> Ainda falta | AB28: ='Comece aqui'!$O$15 -> R$ | AC28: =iferror(AC14-AC27,"") -> 0 | AE28: ='Comece aqui'!$L$71 -> Ainda falta | AF28: ='Comece aqui'!$O$15 -> R$ | AG28: =iferror(AG14-AG27,"") -> 0 | AI28: ='Comece aqui'!$L$71 -> Ainda falta | AJ28: ='Comece aqui'!$O$15 -> R$ | AK28: =iferror(AK14-AK27,"") -> 0 | AM28: ='Comece aqui'!$L$71 -> Ainda falta | AN28: ='Comece aqui'!$O$15 -> R$ | AO28: =iferror(AO14-AO27,"") -> 0 | AQ28: ='Comece aqui'!$L$71 -> Ainda falta | AR28: ='Comece aqui'!$O$15 -> R$ | AS28: =iferror(AS14-AS27,"") -> 0
B29: ='Comece aqui'!$L$41 -> Julho | C29: ='Comece aqui'!$O$15 -> R$ | D29: =Sum(I21,M21,Q21,U21,Y21,AC21,AG21,AK21,AO21,AS21) -> 0
B30: ='Comece aqui'!$L$42 -> Agosto | C30: ='Comece aqui'!$O$15 -> R$ | D30: =Sum(I22,M22,Q22,U22,Y22,AC22,AG22,AK22,AO22,AS22) -> 0
B31: ='Comece aqui'!$L$43 -> Setembro | C31: ='Comece aqui'!$O$15 -> R$ | D31: =Sum(I23,M23,Q23,U23,Y23,AC23,AG23,AK23,AO23,AS23) -> 0
B32: ='Comece aqui'!$L$44 -> Outubro | C32: ='Comece aqui'!$O$15 -> R$ | D32: =Sum(I24,M24,Q24,U24,Y24,AC24,AG24,AK24,AO24,AS24) -> 0
B33: ='Comece aqui'!$L$45 -> Novembro | C33: ='Comece aqui'!$O$15 -> R$ | D33: =Sum(I25,M25,Q25,U25,Y25,AC25,AG25,AK25,AO25,AS25) -> 0
B34: ='Comece aqui'!$L$46 -> Dezembro | C34: ='Comece aqui'!$O$15 -> R$ | D34: =Sum(I26,M26,Q26,U26,Y26,AC26,AG26,AK26,AO26,AS26) -> 0

Sheet EXEMPLOEXAMPLE
A2: ='Comece aqui'!G17 -> Azul/Blue | B2: ='Comece aqui'!L35 -> Janeiro | J2: Saldo | L2: ='Comece aqui'!$O$15 -> R$ | M2: =M30-F54 -> 2818.95 | O2: Entradas | P2: ='Comece aqui'!$O$15 -> R$ | Q2: =M30 -> 3000 | S2: Saídas | U2: ='Comece aqui'!$O$15 -> R$ | V2: =IFS('Comece aqui'!$I$44=TRUE,$F$55,'Comece aqui'!$I$44=FALSE,$F$54) -> 370.95 | X2: Investimentos | AA2: ='Comece aqui'!$O$15 -> R$ | AB2: =M46 -> 100
A3: 1
B5: 2026 | J5: =IFerror(V2/Q2,"") -> 0.12365
B8: =B2&" "&B5 -> Janeiro 2026
B9: ='Comece aqui'!$O34 -> Dom | C9: ='Comece aqui'!$O35 -> Seg | D9: ='Comece aqui'!$O36 -> Ter | E9: ='Comece aqui'!$O37 -> Qua | F9: ='Comece aqui'!$O38 -> Qui | G9: ='Comece aqui'!$O39 -> Sex | H9: ='Comece aqui'!$O40 -> Sab
B10: {=SEQUENCE(6,7,DATE(B5,A3,1)-WEEKDAY(DATE(B5,A3,1)-1))} -> 46019 | C10: 46020 | D10: 46021 | E10: 46022 | F10: 46023 | G10: 46024 | H10: 46025
B11: 46026 | C11: 46027 | D11: 46028 | E11: 46029 | F11: 46030 | G11: 46031 | H11: 46032
B12: 46033 | C12: 46034 | D12: 46035 | E12: 46036 | F12: 46037 | G12: 46038 | H12: 46039
B13: 46040 | C13: 46041 | D13: 46042 | E13: 46043 | F13: 46044 | G13: 46045 | H13: 46046
B14: 46047 | C14: 46048 | D14: 46049 | E14: 46050 | F14: 46051 | G14: 46052 | H14: 46053
B15: 46054 | C15: 46055 | D15: 46056 | E15: 46057 | F15: 46058 | G15: 46059 | H15: 46060
B17: =Iferror(IFS(J5<=50%,'Comece aqui'!O103,J5<=70%,'Comece aqui'!L103,J5<=89%,'Comece aqui'!I103,J5<=100%, 'Comece aqui'!F103,J5<=10000000%,'Comece aqui'!C103),"") | J17: ='Comece aqui'!$R$17 -> Entradas | O17: ='Comece aqui'!R25 -> Gastos fixos | W17: =J51 -> Débito | Z17: Total | AA17: =S20 -> R$ | AB17: =SUM(AB20:AB1000) -> 45.6 | AD17: =J58 -> Crédito | AH17: Total | AI17: =AA20 -> R$ | AJ17: =SUM(AJ20:AJ1000) -> 89.9
O19: ='Comece aqui'!$R$26 -> Nome | P19: ='Comece aqui'!$R$27 -> Data | Q19: ='Comece aqui'!$R$22 -> Categoria | R19: ='Comece aqui'!$R$28 -> Pagamento | S19: ='Comece aqui'!$R$29 -> Valor | U19: FALSE | W19: ='Comece aqui'!$R$26 -> Nome | X19: ='Comece aqui'!$R$27 -> Data | Y19: ='Comece aqui'!$R$22 -> Categoria | Z19: ='Comece aqui'!$R$28 -> Pagamento | AA19: ='Comece aqui'!$R$29 -> Valor | AD19: ='Comece aqui'!$R$26 -> Nome | AE19: ='Comece aqui'!$R$27 -> Data | AF19: ='Comece aqui'!R31 -> Parcela | AG19: ='Comece aqui'!$R$22 -> Categoria | AH19: ='Comece aqui'!$R$28 -> Pagamento | AI19: ='Comece aqui'!$R$29 -> Valor
J20: Salário | L20: ='Comece aqui'!$O$15 -> R$ | M20: 3000 | O20: Conta 1 | P20: 46024 | Q20: Contas | R20: Pix | S20: ='Comece aqui'!$O$15 -> R$ | T20: 123.45 | U20: FALSE | W20: Compra 1 | X20: 46027 | Y20: Despesas eventuais | Z20: Boleto | AA20: ='Comece aqui'!$O$15 -> R$ | AB20: 45.6 | AD20: Compra 2 | AE20: 46028 | AF20: 45992 | AG20: Vestuário | AH20: Crédito 2 | AI20: ='Comece aqui'!$O$15 -> R$ | AJ20: 89.9
L21: ='Comece aqui'!$O$15 -> R$ | O21: Conta 2 | P21: 46025 | Q21: Saúde | R21: Pix | S21: ='Comece aqui'!$O$15 -> R$ | T21: 12 | U21: FALSE | AA21: ='Comece aqui'!$O$15 -> R$ | AI21: ='Comece aqui'!$O$15 -> R$
L22: ='Comece aqui'!$O$15 -> R$ | S22: ='Comece aqui'!$O$15 -> R$ | U22: FALSE | AA22: ='Comece aqui'!$O$15 -> R$ | AI22: ='Comece aqui'!$O$15 -> R$
L23: ='Comece aqui'!$O$15 -> R$ | S23: ='Comece aqui'!$O$15 -> R$ | U23: FALSE | AA23: ='Comece aqui'!$O$15 -> R$ | AI23: ='Comece aqui'!$O$15 -> R$
L24: ='Comece aqui'!$O$15 -> R$ | S24: ='Comece aqui'!$O$15 -> R$ | U24: FALSE | AA24: ='Comece aqui'!$O$15 -> R$ | AI24: ='Comece aqui'!$O$15 -> R$
L25: ='Comece aqui'!$O$15 -> R$ | S25: ='Comece aqui'!$O$15 -> R$ | U25: FALSE | AA25: ='Comece aqui'!$O$15 -> R$ | AI25: ='Comece aqui'!$O$15 -> R$
L26: ='Comece aqui'!$O$15 -> R$ | S26: ='Comece aqui'!$O$15 -> R$ | U26: FALSE | AA26: ='Comece aqui'!$O$15 -> R$ | AI26: ='Comece aqui'!$O$15 -> R$
B27: ='Comece aqui'!R24 -> Metas | L27: ='Comece aqui'!$O$15 -> R$ | S27: ='Comece aqui'!$O$15 -> R$ | U27: FALSE | AA27: ='Comece aqui'!$O$15 -> R$ | AI27: ='Comece aqui'!$O$15 -> R$
L28: ='Comece aqui'!$O$15 -> R$ | S28: ='Comece aqui'!$O$15 -> R$ | U28: FALSE | AA28: ='Comece aqui'!$O$15 -> R$ | AI28: ='Comece aqui'!$O$15 -> R$
B29: FALSE | C29: Aqui também pode escrever, só não pintei de amarelo :)/You can write here too, I just didn't paint it yellow :) | L29: ='Comece aqui'!$O$15 -> R$ | S29: ='Comece aqui'!$O$15 -> R$ | U29: FALSE | AA29: ='Comece aqui'!$O$15 -> R$ | AI29: ='Comece aqui'!$O$15 -> R$
B30: FALSE | J30: ="Total"&" "&J17 -> Total Entradas | L30: ='Comece aqui'!$O$15 -> R$ | M30: =SUM(M20:M29) -> 3000 | S30: ='Comece aqui'!$O$15 -> R$ | U30: FALSE | AA30: ='Comece aqui'!$O$15 -> R$ | AI30: ='Comece aqui'!$O$15 -> R$
B31: FALSE | S31: ='Comece aqui'!$O$15 -> R$ | U31: FALSE | AA31: ='Comece aqui'!$O$15 -> R$ | AI31: ='Comece aqui'!$O$15 -> R$
B32: FALSE | S32: ='Comece aqui'!$O$15 -> R$ | U32: FALSE | AA32: ='Comece aqui'!$O$15 -> R$ | AI32: ='Comece aqui'!$O$15 -> R$
B33: FALSE | J33: ='Comece aqui'!$R$18 -> Investimentos | S33: ='Comece aqui'!$O$15 -> R$ | U33: FALSE | AA33: ='Comece aqui'!$O$15 -> R$ | AI33: ='Comece aqui'!$O$15 -> R$
B34: FALSE | S34: ='Comece aqui'!$O$15 -> R$ | U34: FALSE | AA34: ='Comece aqui'!$O$15 -> R$ | AI34: ='Comece aqui'!$O$15 -> R$
B35: FALSE | S35: ='Comece aqui'!$O$15 -> R$ | U35: FALSE | AA35: ='Comece aqui'!$O$15 -> R$ | AI35: ='Comece aqui'!$O$15 -> R$
B36: FALSE | J36: ='Comece aqui'!$N46 -> Meta/Goal 1 | L36: ='Comece aqui'!$O$15 -> R$ | M36: 100 | S36: ='Comece aqui'!$O$15 -> R$ | U36: FALSE | AA36: ='Comece aqui'!$O$15 -> R$ | AI36: ='Comece aqui'!$O$15 -> R$
B37: FALSE | J37: ='Comece aqui'!$N47 -> Meta/Goal 2 | L37: ='Comece aqui'!$O$15 -> R$ | S37: ='Comece aqui'!$O$15 -> R$ | U37: FALSE | AA37: ='Comece aqui'!$O$15 -> R$ | AI37: ='Comece aqui'!$O$15 -> R$
J38: ='Comece aqui'!$N48 -> Meta/Goal 3 | L38: ='Comece aqui'!$O$15 -> R$ | S38: ='Comece aqui'!$O$15 -> R$ | U38: FALSE | AA38: ='Comece aqui'!$O$15 -> R$ | AI38: ='Comece aqui'!$O$15 -> R$
B39: ='Comece aqui'!$R$23 -> Saídas | J39: ='Comece aqui'!$N49 -> Meta/Goal 4 | L39: ='Comece aqui'!$O$15 -> R$ | S39: ='Comece aqui'!$O$15 -> R$ | U39: FALSE | AA39: ='Comece aqui'!$O$15 -> R$ | AI39: ='Comece aqui'!$O$15 -> R$
J40: ='Comece aqui'!$N50 -> Meta/Goal 5 | L40: ='Comece aqui'!$O$15 -> R$ | O40: Total | S40: ='Comece aqui'!$O$15 -> R$ | T40: =SUM(T20:T39) -> 135.45 | AA40: ='Comece aqui'!$O$15 -> R$ | AI40: ='Comece aqui'!$O$15 -> R$
B41: =J52 -> Débito | E41: ='Comece aqui'!$O$15 -> R$ | F41: =M52 -> 0 | J41: ='Comece aqui'!$N51 -> Meta/Goal 6 | L41: ='Comece aqui'!$O$15 -> R$ | AA41: ='Comece aqui'!$O$15 -> R$ | AI41: ='Comece aqui'!$O$15 -> R$
B42: =J53 -> Pix | E42: ='Comece aqui'!$O$15 -> R$ | F42: =M53 -> 135.45 | J42: ='Comece aqui'!$N52 -> Meta/Goal 7 | L42: ='Comece aqui'!$O$15 -> R$ | AA42: ='Comece aqui'!$O$15 -> R$ | AI42: ='Comece aqui'!$O$15 -> R$
B43: =J54 -> Boleto | E43: ='Comece aqui'!$O$15 -> R$ | F43: =M54 -> 45.6 | J43: ='Comece aqui'!$N53 -> Meta/Goal 8 | L43: ='Comece aqui'!$O$15 -> R$ | O43: ='Comece aqui'!R22 -> Categoria | AA43: ='Comece aqui'!$O$15 -> R$ | AI43: ='Comece aqui'!$O$15 -> R$
B44: =J55 -> Dinheiro | E44: ='Comece aqui'!$O$15 -> R$ | F44: =M55 -> 0 | J44: ='Comece aqui'!$N54 -> Meta/Goal 9 | L44: ='Comece aqui'!$O$15 -> R$ | AA44: ='Comece aqui'!$O$15 -> R$ | AI44: ='Comece aqui'!$O$15 -> R$
B45: =J56 | E45: ='Comece aqui'!$O$15 -> R$ | F45: =M56 -> 0 | J45: ='Comece aqui'!$N55 -> Meta/Goal 10 | L45: ='Comece aqui'!$O$15 -> R$ | O45: ='Comece aqui'!R26 -> Nome | Q45: Limite | R45: ='Comece aqui'!R29 -> Valor | T45: %% | AA45: ='Comece aqui'!$O$15 -> R$ | AI45: ='Comece aqui'!$O$15 -> R$
B46: =J57 | E46: ='Comece aqui'!$O$15 -> R$ | F46: =M57 -> 0 | J46: ="Total"&" "&J33 -> Total Investimentos | L46: ='Comece aqui'!$O$15 -> R$ | M46: =SUM(M36:M45) -> 100 | O46: ='Comece aqui'!$Q37 -> Contas | Q46: 1000 | R46: =SUMIF($Q$20:$Q$39,O46,$T$20:$T$39)+SUMIF($Y$20:$Y$1000,O46,$AB$20:$AB$1000)+SUMIF($AG$20:$AG$1000,O46,$AJ$20:$AJ$1000) -> 123.45 | T46: =IFERROR(R46/Q46,"") -> 0.12345 | AA46: ='Comece aqui'!$O$15 -> R$ | AI46: ='Comece aqui'!$O$15 -> R$
...

Sheet JanuaryJaneiro
A2: ='Comece aqui'!G17 -> Azul/Blue | B2: ='Comece aqui'!L35 -> Janeiro | J2: Saldo | L2: ='Comece aqui'!$O$15 -> R$ | M2: =M30-V2 -> 0 | O2: Entradas | P2: ='Comece aqui'!$O$15 -> R$ | Q2: =M30 -> 0 | S2: Saídas | U2: ='Comece aqui'!$O$15 -> R$ | V2: =IFS('Comece aqui'!$I$44=TRUE,$F$55,'Comece aqui'!$I$44=FALSE,$F$54) -> 0 | X2: Investimentos | AA2: ='Comece aqui'!$O$15 -> R$ | AB2: =M46 -> 0
A3: 1
B5: 2026 | J5: =IFerror(V2/Q2,"")
B8: =B2&" "&B5 -> Janeiro 2026
B9: ='Comece aqui'!$O34 -> Dom | C9: ='Comece aqui'!$O35 -> Seg | D9: ='Comece aqui'!$O36 -> Ter | E9: ='Comece aqui'!$O37 -> Qua | F9: ='Comece aqui'!$O38 -> Qui | G9: ='Comece aqui'!$O39 -> Sex | H9: ='Comece aqui'!$O40 -> Sab
B10: {=SEQUENCE(6,7,DATE(B5,A3,1)-WEEKDAY(DATE(B5,A3,1)-1))} -> 46019 | C10: 46020 | D10: 46021 | E10: 46022 | F10: 46023 | G10: 46024 | H10: 46025
B11: 46026 | C11: 46027 | D11: 46028 | E11: 46029 | F11: 46030 | G11: 46031 | H11: 46032
B12: 46033 | C12: 46034 | D12: 46035 | E12: 46036 | F12: 46037 | G12: 46038 | H12: 46039
B13: 46040 | C13: 46041 | D13: 46042 | E13: 46043 | F13: 46044 | G13: 46045 | H13: 46046
B14: 46047 | C14: 46048 | D14: 46049 | E14: 46050 | F14: 46051 | G14: 46052 | H14: 46053
B15: 46054 | C15: 46055 | D15: 46056 | E15: 46057 | F15: 46058 | G15: 46059 | H15: 46060
B17: =Iferror(IFS(J5<=50%,'Comece aqui'!O103,J5<=70%,'Comece aqui'!L103,J5<=89%,'Comece aqui'!I103,J5<=100%, 'Comece aqui'!F103,J5<=10000000%,'Comece aqui'!C103),"") | J17: ='Comece aqui'!$R$17 -> Entradas | O17: ='Comece aqui'!R25 -> Gastos fixos | W17: =J51 -> Débito | Z17: Total | AA17: =S20 -> R$ | AB17: =SUM(AB20:AB1000) -> 0 | AD17: =J58 -> Crédito | AH17: Total | AI17: =AA20 -> R$ | AJ17: =SUM(AJ20:AJ1000) -> 0
O19: ='Comece aqui'!$R$26 -> Nome | P19: ='Comece aqui'!$R$27 -> Data | Q19: ='Comece aqui'!$R$22 -> Categoria | R19: ='Comece aqui'!$R$28 -> Pagamento | S19: ='Comece aqui'!$R$29 -> Valor | U19: FALSE | W19: ='Comece aqui'!$R$26 -> Nome | X19: ='Comece aqui'!$R$27 -> Data | Y19: ='Comece aqui'!$R$22 -> Categoria | Z19: ='Comece aqui'!$R$28 -> Pagamento | AA19: ='Comece aqui'!$R$29 -> Valor | AD19: ='Comece aqui'!$R$26 -> Nome | AE19: ='Comece aqui'!$R$27 -> Data | AF19: ='Comece aqui'!R31 -> Parcela | AG19: ='Comece aqui'!$R$22 -> Categoria | AH19: ='Comece aqui'!$R$28 -> Pagamento | AI19: ='Comece aqui'!$R$29 -> Valor
L20: ='Comece aqui'!$O$15 -> R$ | S20: ='Comece aqui'!$O$15 -> R$ | U20: FALSE | AA20: ='Comece aqui'!$O$15 -> R$ | AI20: ='Comece aqui'!$O$15 -> R$
L21: ='Comece aqui'!$O$15 -> R$ | S21: ='Comece aqui'!$O$15 -> R$ | U21: FALSE | AA21: ='Comece aqui'!$O$15 -> R$ | AI21: ='Comece aqui'!$O$15 -> R$
L22: ='Comece aqui'!$O$15 -> R$ | S22: ='Comece aqui'!$O$15 -> R$ | U22: FALSE | AA22: ='Comece aqui'!$O$15 -> R$ | AI22: ='Comece aqui'!$O$15 -> R$
L23: ='Comece aqui'!$O$15 -> R$ | S23: ='Comece aqui'!$O$15 -> R$ | U23: FALSE | AA23: ='Comece aqui'!$O$15 -> R$ | AI23: ='Comece aqui'!$O$15 -> R$
L24: ='Comece aqui'!$O$15 -> R$ | S24: ='Comece aqui'!$O$15 -> R$ | U24: FALSE | AA24: ='Comece aqui'!$O$15 -> R$ | AI24: ='Comece aqui'!$O$15 -> R$
L25: ='Comece aqui'!$O$15 -> R$ | S25: ='Comece aqui'!$O$15 -> R$ | U25: FALSE | AA25: ='Comece aqui'!$O$15 -> R$ | AI25: ='Comece aqui'!$O$15 -> R$
L26: ='Comece aqui'!$O$15 -> R$ | S26: ='Comece aqui'!$O$15 -> R$ | U26: FALSE | AA26: ='Comece aqui'!$O$15 -> R$ | AI26: ='Comece aqui'!$O$15 -> R$
B27: ='Comece aqui'!R24 -> Metas | L27: ='Comece aqui'!$O$15 -> R$ | S27: ='Comece aqui'!$O$15 -> R$ | U27: FALSE | AA27: ='Comece aqui'!$O$15 -> R$ | AI27: ='Comece aqui'!$O$15 -> R$
L28: ='Comece aqui'!$O$15 -> R$ | S28: ='Comece aqui'!$O$15 -> R$ | U28: FALSE | AA28: ='Comece aqui'!$O$15 -> R$ | AI28: ='Comece aqui'!$O$15 -> R$
B29: FALSE | L29: ='Comece aqui'!$O$15 -> R$ | S29: ='Comece aqui'!$O$15 -> R$ | U29: FALSE | AA29: ='Comece aqui'!$O$15 -> R$ | AI29: ='Comece aqui'!$O$15 -> R$
B30: FALSE | J30: ="Total"&" "&J17 -> Total Entradas | L30: ='Comece aqui'!$O$15 -> R$ | M30: =SUM(M20:M29) -> 0 | S30: ='Comece aqui'!$O$15 -> R$ | U30: FALSE | AA30: ='Comece aqui'!$O$15 -> R$ | AI30: ='Comece aqui'!$O$15 -> R$
B31: FALSE | S31: ='Comece aqui'!$O$15 -> R$ | U31: FALSE | AA31: ='Comece aqui'!$O$15 -> R$ | AI31: ='Comece aqui'!$O$15 -> R$
B32: FALSE | S32: ='Comece aqui'!$O$15 -> R$ | U32: FALSE | AA32: ='Comece aqui'!$O$15 -> R$ | AI32: ='Comece aqui'!$O$15 -> R$
B33: FALSE | J33: ='Comece aqui'!$R$18 -> Investimentos | S33: ='Comece aqui'!$O$15 -> R$ | U33: FALSE | AA33: ='Comece aqui'!$O$15 -> R$ | AI33: ='Comece aqui'!$O$15 -> R$
B34: FALSE | S34: ='Comece aqui'!$O$15 -> R$ | U34: FALSE | AA34: ='Comece aqui'!$O$15 -> R$ | AI34: ='Comece aqui'!$O$15 -> R$
B35: FALSE | S35: ='Comece aqui'!$O$15 -> R$ | U35: FALSE | AA35: ='Comece aqui'!$O$15 -> R$ | AI35: ='Comece aqui'!$O$15 -> R$
B36: FALSE | J36: ='Comece aqui'!$N46 -> Meta/Goal 1 | L36: ='Comece aqui'!$O$15 -> R$ | S36: ='Comece aqui'!$O$15 -> R$ | U36: FALSE | AA36: ='Comece aqui'!$O$15 -> R$ | AI36: ='Comece aqui'!$O$15 -> R$
B37: FALSE | J37: ='Comece aqui'!$N47 -> Meta/Goal 2 | L37: ='Comece aqui'!$O$15 -> R$ | S37: ='Comece aqui'!$O$15 -> R$ | U37: FALSE | AA37: ='Comece aqui'!$O$15 -> R$ | AI37: ='Comece aqui'!$O$15 -> R$
J38: ='Comece aqui'!$N48 -> Meta/Goal 3 | L38: ='Comece aqui'!$O$15 -> R$ | S38: ='Comece aqui'!$O$15 -> R$ | U38: FALSE | AA38: ='Comece aqui'!$O$15 -> R$ | AI38: ='Comece aqui'!$O$15 -> R$
B39: ='Comece aqui'!$R$23 -> Saídas | J39: ='Comece aqui'!$N49 -> Meta/Goal 4 | L39: ='Comece aqui'!$O$15 -> R$ | S39: ='Comece aqui'!$O$15 -> R$ | U39: FALSE | AA39: ='Comece aqui'!$O$15 -> R$ | AI39: ='Comece aqui'!$O$15 -> R$
J40: ='Comece aqui'!$N50 -> Meta/Goal 5 | L40: ='Comece aqui'!$O$15 -> R$ | O40: Total | S40: ='Comece aqui'!$O$15 -> R$ | T40: =SUMIF(U20:U39,TRUE,T20:T39) -> 0 | AA40: ='Comece aqui'!$O$15 -> R$ | AI40: ='Comece aqui'!$O$15 -> R$
B41: =J52 -> Débito | E41: ='Comece aqui'!$O$15 -> R$ | F41: =M52 -> 0 | J41: ='Comece aqui'!$N51 -> Meta/Goal 6 | L41: ='Comece aqui'!$O$15 -> R$ | AA41: ='Comece aqui'!$O$15 -> R$ | AI41: ='Comece aqui'!$O$15 -> R$
B42: =J53 -> Pix | E42: ='Comece aqui'!$O$15 -> R$ | F42: =M53 -> 0 | J42: ='Comece aqui'!$N52 -> Meta/Goal 7 | L42: ='Comece aqui'!$O$15 -> R$ | AA42: ='Comece aqui'!$O$15 -> R$ | AI42: ='Comece aqui'!$O$15 -> R$
B43: =J54 -> Boleto | E43: ='Comece aqui'!$O$15 -> R$ | F43: =M54 -> 0 | J43: ='Comece aqui'!$N53 -> Meta/Goal 8 | L43: ='Comece aqui'!$O$15 -> R$ | O43: ='Comece aqui'!R22 -> Categoria | AA43: ='Comece aqui'!$O$15 -> R$ | AI43: ='Comece aqui'!$O$15 -> R$
B44: =J55 -> Dinheiro | E44: ='Comece aqui'!$O$15 -> R$ | F44: =M55 -> 0 | J44: ='Comece aqui'!$N54 -> Meta/Goal 9 | L44: ='Comece aqui'!$O$15 -> R$ | AA44: ='Comece aqui'!$O$15 -> R$ | AI44: ='Comece aqui'!$O$15 -> R$
B45: =J56 | E45: ='Comece aqui'!$O$15 -> R$ | F45: =M56 -> 0 | J45: ='Comece aqui'!$N55 -> Meta/Goal 10 | L45: ='Comece aqui'!$O$15 -> R$ | O45: ='Comece aqui'!R26 -> Nome | Q45: Limite | R45: ='Comece aqui'!R29 -> Valor | T45: %% | AA45: ='Comece aqui'!$O$15 -> R$ | AI45: ='Comece aqui'!$O$15 -> R$
B46: =J57 | E46: ='Comece aqui'!$O$15 -> R$ | F46: =M57 -> 0 | J46: ="Total"&" "&J33 -> Total Investimentos | L46: ='Comece aqui'!$O$15 -> R$ | M46: =SUM(M36:M45) -> 0 | O46: ='Comece aqui'!$Q37 -> Contas | R46: =SUMIF($Q$20:$Q$39,O46,$T$20:$T$39)+SUMIF($Y$20:$Y$1000,O46,$AB$20:$AB$1000)+SUMIF($AG$20:$AG$1000,O46,$AJ$20:$AJ$1000) -> 0 | T46: =IFERROR(R46/Q46,"") | AA46: ='Comece aqui'!$O$15 -> R$ | AI46: ='Comece aqui'!$O$15 -> R$
...

Sheet FebruaryFevereiro
A2: ='Comece aqui'!G17 -> Azul/Blue | B2: ='Comece aqui'!L36 -> Fevereiro | J2: Saldo | L2: ='Comece aqui'!$O$15 -> R$ | M2: =M30-V2 -> 0 | O2: Entradas | P2: ='Comece aqui'!$O$15 -> R$ | Q2: =M30 -> 0 | S2: Saídas | U2: ='Comece aqui'!$O$15 -> R$ | V2: =IFS('Comece aqui'!$I$44=TRUE,$F$55,'Comece aqui'!$I$44=FALSE,$F$54) -> 0 | X2: Investimentos | AA2: ='Comece aqui'!$O$15 -> R$ | AB2: =M46 -> 0
A3: 2
B5: 2026 | J5: =IFerror(V2/Q2,"")
B8: =B2&" "&B5 -> Fevereiro 2026
B9: ='Comece aqui'!$O34 -> Dom | C9: ='Comece aqui'!$O35 -> Seg | D9: ='Comece aqui'!$O36 -> Ter | E9: ='Comece aqui'!$O37 -> Qua | F9: ='Comece aqui'!$O38 -> Qui | G9: ='Comece aqui'!$O39 -> Sex | H9: ='Comece aqui'!$O40 -> Sab
B10: {=SEQUENCE(6,7,DATE(B5,A3,1)-WEEKDAY(DATE(B5,A3,1)-1))} -> 46047 | C10: 46048 | D10: 46049 | E10: 46050 | F10: 46051 | G10: 46052 | H10: 46053
B11: 46054 | C11: 46055 | D11: 46056 | E11: 46057 | F11: 46058 | G11: 46059 | H11: 46060
B12: 46061 | C12: 46062 | D12: 46063 | E12: 46064 | F12: 46065 | G12: 46066 | H12: 46067
B13: 46068 | C13: 46069 | D13: 46070 | E13: 46071 | F13: 46072 | G13: 46073 | H13: 46074
B14: 46075 | C14: 46076 | D14: 46077 | E14: 46078 | F14: 46079 | G14: 46080 | H14: 46081
B15: 46082 | C15: 46083 | D15: 46084 | E15: 46085 | F15: 46086 | G15: 46087 | H15: 46088
B17: =Iferror(IFS(J5<=50%,'Comece aqui'!O103,J5<=70%,'Comece aqui'!L103,J5<=89%,'Comece aqui'!I103,J5<=100%, 'Comece aqui'!F103,J5<=10000000%,'Comece aqui'!C103),"") | J17: ='Comece aqui'!$R$17 -> Entradas | O17: ='Comece aqui'!R25 -> Gastos fixos | W17: =J51 -> Débito | Z17: Total | AA17: =S20 -> R$ | AB17: =SUM(AB20:AB1000) -> 0 | AD17: =J58 -> Crédito | AH17: Total | AI17: =AA20 -> R$ | AJ17: =SUM(AJ20:AJ1000) -> 0
O19: ='Comece aqui'!$R$26 -> Nome | P19: ='Comece aqui'!$R$27 -> Data | Q19: ='Comece aqui'!$R$22 -> Categoria | R19: ='Comece aqui'!$R$28 -> Pagamento | S19: ='Comece aqui'!$R$29 -> Valor | U19: FALSE | W19: ='Comece aqui'!$R$26 -> Nome | X19: ='Comece aqui'!$R$27 -> Data | Y19: ='Comece aqui'!$R$22 -> Categoria | Z19: ='Comece aqui'!$R$28 -> Pagamento | AA19: ='Comece aqui'!$R$29 -> Valor | AD19: ='Comece aqui'!$R$26 -> Nome | AE19: ='Comece aqui'!$R$27 -> Data | AF19: ='Comece aqui'!R31 -> Parcela | AG19: ='Comece aqui'!$R$22 -> Categoria | AH19: ='Comece aqui'!$R$28 -> Pagamento | AI19: ='Comece aqui'!$R$29 -> Valor
L20: ='Comece aqui'!$O$15 -> R$ | S20: ='Comece aqui'!$O$15 -> R$ | U20: FALSE | AA20: ='Comece aqui'!$O$15 -> R$ | AI20: ='Comece aqui'!$O$15 -> R$
L21: ='Comece aqui'!$O$15 -> R$ | S21: ='Comece aqui'!$O$15 -> R$ | U21: FALSE | AA21: ='Comece aqui'!$O$15 -> R$ | AI21: ='Comece aqui'!$O$15 -> R$
L22: ='Comece aqui'!$O$15 -> R$ | S22: ='Comece aqui'!$O$15 -> R$ | U22: FALSE | AA22: ='Comece aqui'!$O$15 -> R$ | AI22: ='Comece aqui'!$O$15 -> R$
L23: ='Comece aqui'!$O$15 -> R$ | S23: ='Comece aqui'!$O$15 -> R$ | U23: FALSE | AA23: ='Comece aqui'!$O$15 -> R$ | AI23: ='Comece aqui'!$O$15 -> R$
L24: ='Comece aqui'!$O$15 -> R$ | S24: ='Comece aqui'!$O$15 -> R$ | U24: FALSE | AA24: ='Comece aqui'!$O$15 -> R$ | AI24: ='Comece aqui'!$O$15 -> R$
L25: ='Comece aqui'!$O$15 -> R$ | S25: ='Comece aqui'!$O$15 -> R$ | U25: FALSE | AA25: ='Comece aqui'!$O$15 -> R$ | AI25: ='Comece aqui'!$O$15 -> R$
L26: ='Comece aqui'!$O$15 -> R$ | S26: ='Comece aqui'!$O$15 -> R$ | U26: FALSE | AA26: ='Comece aqui'!$O$15 -> R$ | AI26: ='Comece aqui'!$O$15 -> R$
B27: ='Comece aqui'!R24 -> Metas | L27: ='Comece aqui'!$O$15 -> R$ | S27: ='Comece aqui'!$O$15 -> R$ | U27: FALSE | AA27: ='Comece aqui'!$O$15 -> R$ | AI27: ='Comece aqui'!$O$15 -> R$
L28: ='Comece aqui'!$O$15 -> R$ | S28: ='Comece aqui'!$O$15 -> R$ | U28: FALSE | AA28: ='Comece aqui'!$O$15 -> R$ | AI28: ='Comece aqui'!$O$15 -> R$
B29: FALSE | L29: ='Comece aqui'!$O$15 -> R$ | S29: ='Comece aqui'!$O$15 -> R$ | U29: FALSE | AA29: ='Comece aqui'!$O$15 -> R$ | AI29: ='Comece aqui'!$O$15 -> R$
B30: FALSE | J30: ="Total"&" "&J17 -> Total Entradas | L30: ='Comece aqui'!$O$15 -> R$ | M30: =SUM(M20:M29) -> 0 | S30: ='Comece aqui'!$O$15 -> R$ | U30: FALSE | AA30: ='Comece aqui'!$O$15 -> R$ | AI30: ='Comece aqui'!$O$15 -> R$
B31: FALSE | S31: ='Comece aqui'!$O$15 -> R$ | U31: FALSE | AA31: ='Comece aqui'!$O$15 -> R$ | AI31: ='Comece aqui'!$O$15 -> R$
B32: FALSE | S32: ='Comece aqui'!$O$15 -> R$ | U32: FALSE | AA32: ='Comece aqui'!$O$15 -> R$ | AI32: ='Comece aqui'!$O$15 -> R$
B33: FALSE | J33: ='Comece aqui'!$R$18 -> Investimentos | S33: ='Comece aqui'!$O$15 -> R$ | U33: FALSE | AA33: ='Comece aqui'!$O$15 -> R$ | AI33: ='Comece aqui'!$O$15 -> R$
B34: FALSE | S34: ='Comece aqui'!$O$15 -> R$ | U34: FALSE | AA34: ='Comece aqui'!$O$15 -> R$ | AI34: ='Comece aqui'!$O$15 -> R$
B35: FALSE | S35: ='Comece aqui'!$O$15 -> R$ | U35: FALSE | AA35: ='Comece aqui'!$O$15 -> R$ | AI35: ='Comece aqui'!$O$15 -> R$
B36: FALSE | J36: ='Comece aqui'!$N46 -> Meta/Goal 1 | L36: ='Comece aqui'!$O$15 -> R$ | S36: ='Comece aqui'!$O$15 -> R$ | U36: FALSE | AA36: ='Comece aqui'!$O$15 -> R$ | AI36: ='Comece aqui'!$O$15 -> R$
B37: FALSE | J37: ='Comece aqui'!$N47 -> Meta/Goal 2 | L37: ='Comece aqui'!$O$15 -> R$ | S37: ='Comece aqui'!$O$15 -> R$ | U37: FALSE | AA37: ='Comece aqui'!$O$15 -> R$ | AI37: ='Comece aqui'!$O$15 -> R$
J38: ='Comece aqui'!$N48 -> Meta/Goal 3 | L38: ='Comece aqui'!$O$15 -> R$ | S38: ='Comece aqui'!$O$15 -> R$ | U38: FALSE | AA38: ='Comece aqui'!$O$15 -> R$ | AI38: ='Comece aqui'!$O$15 -> R$
B39: ='Comece aqui'!$R$23 -> Saídas | J39: ='Comece aqui'!$N49 -> Meta/Goal 4 | L39: ='Comece aqui'!$O$15 -> R$ | S39: ='Comece aqui'!$O$15 -> R$ | U39: FALSE | AA39: ='Comece aqui'!$O$15 -> R$ | AI39: ='Comece aqui'!$O$15 -> R$
J40: ='Comece aqui'!$N50 -> Meta/Goal 5 | L40: ='Comece aqui'!$O$15 -> R$ | O40: Total | S40: ='Comece aqui'!$O$15 -> R$ | T40: =SUMIF(U20:U39,TRUE,T20:T39) -> 0 | AA40: ='Comece aqui'!$O$15 -> R$ | AI40: ='Comece aqui'!$O$15 -> R$
B41: =J52 -> Débito | E41: ='Comece aqui'!$O$15 -> R$ | F41: =M52 -> 0 | J41: ='Comece aqui'!$N51 -> Meta/Goal 6 | L41: ='Comece aqui'!$O$15 -> R$ | AA41: ='Comece aqui'!$O$15 -> R$ | AI41: ='Comece aqui'!$O$15 -> R$
B42: =J53 -> Pix | E42: ='Comece aqui'!$O$15 -> R$ | F42: =M53 -> 0 | J42: ='Comece aqui'!$N52 -> Meta/Goal 7 | L42: ='Comece aqui'!$O$15 -> R$ | AA42: ='Comece aqui'!$O$15 -> R$ | AI42: ='Comece aqui'!$O$15 -> R$
B43: =J54 -> Boleto | E43: ='Comece aqui'!$O$15 -> R$ | F43: =M54 -> 0 | J43: ='Comece aqui'!$N53 -> Meta/Goal 8 | L43: ='Comece aqui'!$O$15 -> R$ | O43: ='Comece aqui'!R22 -> Categoria | AA43: ='Comece aqui'!$O$15 -> R$ | AI43: ='Comece aqui'!$O$15 -> R$
B44: =J55 -> Dinheiro | E44: ='Comece aqui'!$O$15 -> R$ | F44: =M55 -> 0 | J44: ='Comece aqui'!$N54 -> Meta/Goal 9 | L44: ='Comece aqui'!$O$15 -> R$ | AA44: ='Comece aqui'!$O$15 -> R$ | AI44: ='Comece aqui'!$O$15 -> R$
B45: =J56 | E45: ='Comece aqui'!$O$15 -> R$ | F45: =M56 -> 0 | J45: ='Comece aqui'!$N55 -> Meta/Goal 10 | L45: ='Comece aqui'!$O$15 -> R$ | O45: ='Comece aqui'!R26 -> Nome | Q45: Limite | R45: ='Comece aqui'!R29 -> Valor | T45: %% | AA45: ='Comece aqui'!$O$15 -> R$ | AI45: ='Comece aqui'!$O$15 -> R$
B46: =J57 | E46: ='Comece aqui'!$O$15 -> R$ | F46: =M57 -> 0 | J46: ="Total"&" "&J33 -> Total Investimentos | L46: ='Comece aqui'!$O$15 -> R$ | M46: =SUM(M36:M45) -> 0 | O46: ='Comece aqui'!$Q37 -> Contas | R46: =SUMIF($Q$20:$Q$39,O46,$T$20:$T$39)+SUMIF($Y$20:$Y$1000,O46,$AB$20:$AB$1000)+SUMIF($AG$20:$AG$1000,O46,$AJ$20:$AJ$1000) -> 0 | T46: =IFERROR(R46/Q46,"") | AA46: ='Comece aqui'!$O$15 -> R$ | AI46: ='Comece aqui'!$O$15 -> R$
...

Sheet MarchMarço
A2: ='Comece aqui'!G17 -> Azul/Blue | B2: ='Comece aqui'!L37 -> Março | J2: Saldo | L2: ='Comece aqui'!$O$15 -> R$ | M2: =M30-V2 -> 0 | O2: Entradas | P2: ='Comece aqui'!$O$15 -> R$ | Q2: =M30 -> 0 | S2: Saídas | U2: ='Comece aqui'!$O$15 -> R$ | V2: =IFS('Comece aqui'!$I$44=TRUE,$F$55,'Comece aqui'!$I$44=FALSE,$F$54) -> 0 | X2: Investimentos | AA2: ='Comece aqui'!$O$15 -> R$ | AB2: =M46 -> 0
A3: 3
B5: 2026 | J5: =IFerror(V2/Q2,"")
B8: =B2&" "&B5 -> Março 2026
B9: ='Comece aqui'!$O34 -> Dom | C9: ='Comece aqui'!$O35 -> Seg | D9: ='Comece aqui'!$O36 -> Ter | E9: ='Comece aqui'!$O37 -> Qua | F9: ='Comece aqui'!$O38 -> Qui | G9: ='Comece aqui'!$O39 -> Sex | H9: ='Comece aqui'!$O40 -> Sab
B10: {=SEQUENCE(6,7,DATE(B5,A3,1)-WEEKDAY(DATE(B5,A3,1)-1))} -> 46075 | C10: 46076 | D10: 46077 | E10: 46078 | F10: 46079 | G10: 46080 | H10: 46081
B11: 46082 | C11: 46083 | D11: 46084 | E11: 46085 | F11: 46086 | G11: 46087 | H11: 46088
B12: 46089 | C12: 46090 | D12: 46091 | E12: 46092 | F12: 46093 | G12: 46094 | H12: 46095
B13: 46096 | C13: 46097 | D13: 46098 | E13: 46099 | F13: 46100 | G13: 46101 | H13: 46102
B14: 46103 | C14: 46104 | D14: 46105 | E14: 46106 | F14: 46107 | G14: 46108 | H14: 46109
B15: 46110 | C15: 46111 | D15: 46112 | E15: 46113 | F15: 46114 | G15: 46115 | H15: 46116
B17: =Iferror(IFS(J5<=50%,'Comece aqui'!O103,J5<=70%,'Comece aqui'!L103,J5<=89%,'Comece aqui'!I103,J5<=100%, 'Comece aqui'!F103,J5<=10000000%,'Comece aqui'!C103),"") | J17: ='Comece aqui'!$R$17 -> Entradas | O17: ='Comece aqui'!R25 -> Gastos fixos | W17: =J51 -> Débito | Z17: Total | AA17: =S20 -> R$ | AB17: =SUM(AB20:AB1000) -> 0 | AD17: =J58 -> Crédito | AH17: Total | AI17: =AA20 -> R$ | AJ17: =SUM(AJ20:AJ1000) -> 0
O19: ='Comece aqui'!$R$26 -> Nome | P19: ='Comece aqui'!$R$27 -> Data | Q19: ='Comece aqui'!$R$22 -> Categoria | R19: ='Comece aqui'!$R$28 -> Pagamento | S19: ='Comece aqui'!$R$29 -> Valor | U19: FALSE | W19: ='Comece aqui'!$R$26 -> Nome | X19: ='Comece aqui'!$R$27 -> Data | Y19: ='Comece aqui'!$R$22 -> Categoria | Z19: ='Comece aqui'!$R$28 -> Pagamento | AA19: ='Comece aqui'!$R$29 -> Valor | AD19: ='Comece aqui'!$R$26 -> Nome | AE19: ='Comece aqui'!$R$27 -> Data | AF19: ='Comece aqui'!R31 -> Parcela | AG19: ='Comece aqui'!$R$22 -> Categoria | AH19: ='Comece aqui'!$R$28 -> Pagamento | AI19: ='Comece aqui'!$R$29 -> Valor
L20: ='Comece aqui'!$O$15 -> R$ | S20: ='Comece aqui'!$O$15 -> R$ | U20: FALSE | AA20: ='Comece aqui'!$O$15 -> R$ | AI20: ='Comece aqui'!$O$15 -> R$
L21: ='Comece aqui'!$O$15 -> R$ | S21: ='Comece aqui'!$O$15 -> R$ | U21: FALSE | AA21: ='Comece aqui'!$O$15 -> R$ | AI21: ='Comece aqui'!$O$15 -> R$
L22: ='Comece aqui'!$O$15 -> R$ | S22: ='Comece aqui'!$O$15 -> R$ | U22: FALSE | AA22: ='Comece aqui'!$O$15 -> R$ | AI22: ='Comece aqui'!$O$15 -> R$
L23: ='Comece aqui'!$O$15 -> R$ | S23: ='Comece aqui'!$O$15 -> R$ | U23: FALSE | AA23: ='Comece aqui'!$O$15 -> R$ | AI23: ='Comece aqui'!$O$15 -> R$
L24: ='Comece aqui'!$O$15 -> R$ | S24: ='Comece aqui'!$O$15 -> R$ | U24: FALSE | AA24: ='Comece aqui'!$O$15 -> R$ | AI24: ='Comece aqui'!$O$15 -> R$
L25: ='Comece aqui'!$O$15 -> R$ | S25: ='Comece aqui'!$O$15 -> R$ | U25: FALSE | AA25: ='Comece aqui'!$O$15 -> R$ | AI25: ='Comece aqui'!$O$15 -> R$
L26: ='Comece aqui'!$O$15 -> R$ | S26: ='Comece aqui'!$O$15 -> R$ | U26: FALSE | AA26: ='Comece aqui'!$O$15 -> R$ | AI26: ='Comece aqui'!$O$15 -> R$
B27: ='Comece aqui'!R24 -> Metas | L27: ='Comece aqui'!$O$15 -> R$ | S27: ='Comece aqui'!$O$15 -> R$ | U27: FALSE | AA27: ='Comece aqui'!$O$15 -> R$ | AI27: ='Comece aqui'!$O$15 -> R$
L28: ='Comece aqui'!$O$15 -> R$ | S28: ='Comece aqui'!$O$15 -> R$ | U28: FALSE | AA28: ='Comece aqui'!$O$15 -> R$ | AI28: ='Comece aqui'!$O$15 -> R$
B29: FALSE | L29: ='Comece aqui'!$O$15 -> R$ | S29: ='Comece aqui'!$O$15 -> R$ | U29: FALSE | AA29: ='Comece aqui'!$O$15 -> R$ | AI29: ='Comece aqui'!$O$15 -> R$
